Workbook

Sheet 使い方
A1: ポスポス 導入店の聞き取りシート
A2: 今使っているお店に30分で話を聞き、どれだけ楽になったかを数字で残して、紹介をお願いするためのシートです。
A4: 使い方
A5: 1. お店ごとに「店舗1」「店舗2」「店舗3」のシートを使います（足りなければシートを複製して、名前を「店舗4」などにします）。
A6: 2. 黄色のセルに書き込みます。灰色のセル（減った量・減った割合・紹介をお願いするかの判定）は自動で計算します。
A7: 3. 「記入例」のシートに、書き方の見本があります（架空のお店です）。
A8: 4. 「一覧」のシートに、店舗1〜3の大事な数字が自動でまとまります。
A10: 気をつけること
A11: ・数字は実際に測ったものだけを書きます。わからないところは空けておき、来月測ってもらいます。広告やメールに使うのは、測った数字だけです。
A12: ・導入事例に使うときは、必ず先にお店に文を見せて確認してもらいます。
A13: ・すすめたい度合いが6点以下のお店には、紹介はお願いせず、困っていることを先に直します。

Sheet 一覧
A1: 一覧（店舗1〜3から自動でまとまります。ここには書き込みません）
A3: 店舗 | B3: お店の名前 | C3: 種類 | D3: 聞いた日 | E3: プラン | F3: 閉店後の締め（売上の集計・レジ締め）（分／日）導入前 | G3: 今 | H3: 減った割合 | I3: 給料の計算（バック・時給・手当を含む）（時間／月）導入前 | J3: 今 | K3: 減った割合 | L3: シフトを集めて決める時間（時間／月）導入前 | M3: 今 | N3: 減った割合 | O3: 給料・バックの問い合わせ（回／月）導入前 | P3: 今 | Q3: 減った割合 | R3: 計算のまちがい・やり直し（回／月）導入前 | S3: 今 | T3: 減った割合 | U3: 面接にかけた時間（分／人）導入前 | V3: 今 | W3: 減った割合 | X3: 面接のドタキャン・来ない（人／月）導入前 | Y3: 今 | Z3: 減った割合 | AA3: 合わなかった体入（夜のお店）（人／月）導入前 | AB3: 今 | AC3: 減った割合 | AD3: 合わなかった体入にかかった体入費（夜のお店）（円／月）導入前 | AE3: 今 | AF3: 減った割合 | AG3: AI面接を使った回数（回／月） | AH3: 会った人 | AI3: 採用した人 | AJ3: すすめたい度合い（0〜10） | AK3: なくなったら | AL3: 導入事例 | AM3: 紹介先の数 | AN3: 見出しの一文
A4: ="店舗1" -> 店舗1 | B4: =IF(店舗1!C6="","",店舗1!C6) | C4: =IF(店舗1!C7="","",店舗1!C7) | D4: =IF(店舗1!C5="","",店舗1!C5) | E4: =IF(店舗1!C10="","",店舗1!C10) | F4: =IF(店舗1!C25="","",店舗1!C25) | G4: =IF(店舗1!D25="","",店舗1!D25) | H4: =IF(店舗1!F25="","",店舗1!F25) | I4: =IF(店舗1!C26="","",店舗1!C26) | J4: =IF(店舗1!D26="","",店舗1!D26) | K4: =IF(店舗1!F26="","",店舗1!F26) | L4: =IF(店舗1!C27="","",店舗1!C27) | M4: =IF(店舗1!D27="","",店舗1!D27) | N4: =IF(店舗1!F27="","",店舗1!F27) | O4: =IF(店舗1!C28="","",店舗1!C28) | P4: =IF(店舗1!D28="","",店舗1!D28) | Q4: =IF(店舗1!F28="","",店舗1!F28) | R4: =IF(店舗1!C29="","",店舗1!C29) | S4: =IF(店舗1!D29="","",店舗1!D29) | T4: =IF(店舗1!F29="","",店舗1!F29) | U4: =IF(店舗1!C30="","",店舗1!C30) | V4: =IF(店舗1!D30="","",店舗1!D30) | W4: =IF(店舗1!F30="","",店舗1!F30) | X4: =IF(店舗1!C31="","",店舗1!C31) | Y4: =IF(店舗1!D31="","",店舗1!D31) | Z4: =IF(店舗1!F31="","",店舗1!F31) | AA4: =IF(店舗1!C32="","",店舗1!C32) | AB4: =IF(店舗1!D32="","",店舗1!D32) | AC4: =IF(店舗1!F32="","",店舗1!F32) | AD4: =IF(店舗1!C33="","",店舗1!C33) | AE4: =IF(店舗1!D33="","",店舗1!D33) | AF4: =IF(店舗1!F33="","",店舗1!F33) | AG4: =IF(店舗1!D34="","",店舗1!D34) | AH4: =IF(店舗1!D35="","",店舗1!D35) | AI4: =IF(店舗1!D36="","",店舗1!D36) | AJ4: =IF(店舗1!C57="","",店舗1!C57) | AK4: =IF(店舗1!C59="","",店舗1!C59) | AL4: =IF(店舗1!C67="","",店舗1!C67) | AM4: =COUNTA(店舗1!A63:A65) -> 0 | AN4: =IF(店舗1!C37="","",店舗1!C37)
A5: ="店舗2" -> 店舗2 | B5: =IF(店舗2!C6="","",店舗2!C6) | C5: =IF(店舗2!C7="","",店舗2!C7) | D5: =IF(店舗2!C5="","",店舗2!C5) | E5: =IF(店舗2!C10="","",店舗2!C10) | F5: =IF(店舗2!C25="","",店舗2!C25) | G5: =IF(店舗2!D25="","",店舗2!D25) | H5: =IF(店舗2!F25="","",店舗2!F25) | I5: =IF(店舗2!C26="","",店舗2!C26) | J5: =IF(店舗2!D26="","",店舗2!D26) | K5: =IF(店舗2!F26="","",店舗2!F26) | L5: =IF(店舗2!C27="","",店舗2!C27) | M5: =IF(店舗2!D27="","",店舗2!D27) | N5: =IF(店舗2!F27="","",店舗2!F27) | O5: =IF(店舗2!C28="","",店舗2!C28) | P5: =IF(店舗2!D28="","",店舗2!D28) | Q5: =IF(店舗2!F28="","",店舗2!F28) | R5: =IF(店舗2!C29="","",店舗2!C29) | S5: =IF(店舗2!D29="","",店舗2!D29) | T5: =IF(店舗2!F29="","",店舗2!F29) | U5: =IF(店舗2!C30="","",店舗2!C30) | V5: =IF(店舗2!D30="","",店舗2!D30) | W5: =IF(店舗2!F30="","",店舗2!F30) | X5: =IF(店舗2!C31="","",店舗2!C31) | Y5: =IF(店舗2!D31="","",店舗2!D31) | Z5: =IF(店舗2!F31="","",店舗2!F31) | AA5: =IF(店舗2!C32="","",店舗2!C32) | AB5: =IF(店舗2!D32="","",店舗2!D32) | AC5: =IF(店舗2!F32="","",店舗2!F32) | AD5: =IF(店舗2!C33="","",店舗2!C33) | AE5: =IF(店舗2!D33="","",店舗2!D33) | AF5: =IF(店舗2!F33="","",店舗2!F33) | AG5: =IF(店舗2!D34="","",店舗2!D34) | AH5: =IF(店舗2!D35="","",店舗2!D35) | AI5: =IF(店舗2!D36="","",店舗2!D36) | AJ5: =IF(店舗2!C57="","",店舗2!C57) | AK5: =IF(店舗2!C59="","",店舗2!C59) | AL5: =IF(店舗2!C67="","",店舗2!C67) | AM5: =COUNTA(店舗2!A63:A65) -> 0 | AN5: =IF(店舗2!C37="","",店舗2!C37)
A6: ="店舗3" -> 店舗3 | B6: =IF(店舗3!C6="","",店舗3!C6) | C6: =IF(店舗3!C7="","",店舗3!C7) | D6: =IF(店舗3!C5="","",店舗3!C5) | E6: =IF(店舗3!C10="","",店舗3!C10) | F6: =IF(店舗3!C25="","",店舗3!C25) | G6: =IF(店舗3!D25="","",店舗3!D25) | H6: =IF(店舗3!F25="","",店舗3!F25) | I6: =IF(店舗3!C26="","",店舗3!C26) | J6: =IF(店舗3!D26="","",店舗3!D26) | K6: =IF(店舗3!F26="","",店舗3!F26) | L6: =IF(店舗3!C27="","",店舗3!C27) | M6: =IF(店舗3!D27="","",店舗3!D27) | N6: =IF(店舗3!F27="","",店舗3!F27) | O6: =IF(店舗3!C28="","",店舗3!C28) | P6: =IF(店舗3!D28="","",店舗3!D28) | Q6: =IF(店舗3!F28="","",店舗3!F28) | R6: =IF(店舗3!C29="","",店舗3!C29) | S6: =IF(店舗3!D29="","",店舗3!D29) | T6: =IF(店舗3!F29="","",店舗3!F29) | U6: =IF(店舗3!C30="","",店舗3!C30) | V6: =IF(店舗3!D30="","",店舗3!D30) | W6: =IF(店舗3!F30="","",店舗3!F30) | X6: =IF(店舗3!C31="","",店舗3!C31) | Y6: =IF(店舗3!D31="","",店舗3!D31) | Z6: =IF(店舗3!F31="","",店舗3!F31) | AA6: =IF(店舗3!C32="","",店舗3!C32) | AB6: =IF(店舗3!D32="","",店舗3!D32) | AC6: =IF(店舗3!F32="","",店舗3!F32) | AD6: =IF(店舗3!C33="","",店舗3!C33) | AE6: =IF(店舗3!D33="","",店舗3!D33) | AF6: =IF(店舗3!F33="","",店舗3!F33) | AG6: =IF(店舗3!D34="","",店舗3!D34) | AH6: =IF(店舗3!D35="","",店舗3!D35) | AI6: =IF(店舗3!D36="","",店舗3!D36) | AJ6: =IF(店舗3!C57="","",店舗3!C57) | AK6: =IF(店舗3!C59="","",店舗3!C59) | AL6: =IF(店舗3!C67="","",店舗3!C67) | AM6: =COUNTA(店舗3!A63:A65) -> 0 | AN6: =IF(店舗3!C37="","",店舗3!C37)

Sheet 店舗1
A1: ポスポス 導入店の聞き取りシート
A2: 黄色のセルに書き込みます。灰色のセルは自動で計算します。数字は実際に測ったものだけを書き、わからないところは空けておきます（広告に使うのは測った数字だけ）。
A4: 1. お店の情報
A5: 聞いた日
A6: お店の名前
A7: お店の種類
A8: 話を聞いた人（役職）
A9: 使い始めた日
A10: プラン
A11: 店舗数
A12: スタッフ・キャストの人数
A13: 前に使っていたレジ・管理の方法
... A23: 3. 数字で測ること
A24: 測ること | B24: 単位 | C24: 導入前 | D24: 今 | E24: 減った量 | F24: 減った割合 | G24: どうやって測ったか
A25: 閉店後の締め（売上の集計・レジ締め） | B25: 分／日 | E25: =IF(OR(C25="",D25=""),"",C25-D25) | F25: =IF(OR(C25="",D25="",N(C25)=0),"",(C25-D25)/C25)
A26: 給料の計算（バック・時給・手当を含む） | B26: 時間／月 | E26: =IF(OR(C26="",D26=""),"",C26-D26) | F26: =IF(OR(C26="",D26="",N(C26)=0),"",(C26-D26)/C26)
A27: シフトを集めて決める時間 | B27: 時間／月 | E27: =IF(OR(C27="",D27=""),"",C27-D27) | F27: =IF(OR(C27="",D27="",N(C27)=0),"",(C27-D27)/C27)
A28: 給料・バックの問い合わせ | B28: 回／月 | E28: =IF(OR(C28="",D28=""),"",C28-D28) | F28: =IF(OR(C28="",D28="",N(C28)=0),"",(C28-D28)/C28)
A29: 計算のまちがい・やり直し | B29: 回／月 | E29: =IF(OR(C29="",D29=""),"",C29-D29) | F29: =IF(OR(C29="",D29="",N(C29)=0),"",(C29-D29)/C29)
A30: 面接にかけた時間 | B30: 分／人 | E30: =IF(OR(C30="",D30=""),"",C30-D30) | F30: =IF(OR(C30="",D30="",N(C30)=0),"",(C30-D30)/C30)
A31: 面接のドタキャン・来ない | B31: 人／月 | E31: =IF(OR(C31="",D31=""),"",C31-D31) | F31: =IF(OR(C31="",D31="",N(C31)=0),"",(C31-D31)/C31)
A32: 合わなかった体入（夜のお店） | B32: 人／月 | E32: =IF(OR(C32="",D32=""),"",C32-D32) | F32: =IF(OR(C32="",D32="",N(C32)=0),"",(C32-D32)/C32)
A33: 合わなかった体入にかかった体入費（夜のお店） | B33: 円／月 | E33: =IF(OR(C33="",D33=""),"",C33-D33) | F33: =IF(OR(C33="",D33="",N(C33)=0),"",(C33-D33)/C33)
A34: AI面接を使った回数 | B34: 回／月 | C34: ―
A35: AI面接のあと会った人 | B35: 人／月 | C35: ―
A36: AI面接のあと採用した人 | B36: 人／月 | C36: ―
A37: 導入事例の見出しになる一文 「◯◯が、◯◯から◯◯になった」
A39: 4. 使っている機能と、不満・要望
A40: 機能 | B40: 使い方（選ぶ） | D40: 使っていない理由
A41: 注文・会計・伝票
A42: セット料金・延長・指名・付け回し（夜）
A43: QR注文・厨房の画面（昼）
A44: 打刻・シフト
A45: 給料・バックの計算
A46: スタッフ・キャストのスマホ画面
A47: 顧客・ボトル・売掛・ポイント
A48: お金・日報・利益
A49: AI面接
A50: いちばん助かっている機能は？それはなぜ？
A51: 使いにくいところ・わかりにくいところは？
...

Sheet 店舗2
A1: ポスポス 導入店の聞き取りシート
A2: 黄色のセルに書き込みます。灰色のセルは自動で計算します。数字は実際に測ったものだけを書き、わからないところは空けておきます（広告に使うのは測った数字だけ）。
A4: 1. お店の情報
A5: 聞いた日
A6: お店の名前
A7: お店の種類
A8: 話を聞いた人（役職）
A9: 使い始めた日
A10: プラン
A11: 店舗数
A12: スタッフ・キャストの人数
A13: 前に使っていたレジ・管理の方法
... A23: 3. 数字で測ること
A24: 測ること | B24: 単位 | C24: 導入前 | D24: 今 | E24: 減った量 | F24: 減った割合 | G24: どうやって測ったか
A25: 閉店後の締め（売上の集計・レジ締め） | B25: 分／日 | E25: =IF(OR(C25="",D25=""),"",C25-D25) | F25: =IF(OR(C25="",D25="",N(C25)=0),"",(C25-D25)/C25)
A26: 給料の計算（バック・時給・手当を含む） | B26: 時間／月 | E26: =IF(OR(C26="",D26=""),"",C26-D26) | F26: =IF(OR(C26="",D26="",N(C26)=0),"",(C26-D26)/C26)
A27: シフトを集めて決める時間 | B27: 時間／月 | E27: =IF(OR(C27="",D27=""),"",C27-D27) | F27: =IF(OR(C27="",D27="",N(C27)=0),"",(C27-D27)/C27)
A28: 給料・バックの問い合わせ | B28: 回／月 | E28: =IF(OR(C28="",D28=""),"",C28-D28) | F28: =IF(OR(C28="",D28="",N(C28)=0),"",(C28-D28)/C28)
A29: 計算のまちがい・やり直し | B29: 回／月 | E29: =IF(OR(C29="",D29=""),"",C29-D29) | F29: =IF(OR(C29="",D29="",N(C29)=0),"",(C29-D29)/C29)
A30: 面接にかけた時間 | B30: 分／人 | E30: =IF(OR(C30="",D30=""),"",C30-D30) | F30: =IF(OR(C30="",D30="",N(C30)=0),"",(C30-D30)/C30)
A31: 面接のドタキャン・来ない | B31: 人／月 | E31: =IF(OR(C31="",D31=""),"",C31-D31) | F31: =IF(OR(C31="",D31="",N(C31)=0),"",(C31-D31)/C31)
A32: 合わなかった体入（夜のお店） | B32: 人／月 | E32: =IF(OR(C32="",D32=""),"",C32-D32) | F32: =IF(OR(C32="",D32="",N(C32)=0),"",(C32-D32)/C32)
A33: 合わなかった体入にかかった体入費（夜のお店） | B33: 円／月 | E33: =IF(OR(C33="",D33=""),"",C33-D33) | F33: =IF(OR(C33="",D33="",N(C33)=0),"",(C33-D33)/C33)
A34: AI面接を使った回数 | B34: 回／月 | C34: ―
A35: AI面接のあと会った人 | B35: 人／月 | C35: ―
A36: AI面接のあと採用した人 | B36: 人／月 | C36: ―
A37: 導入事例の見出しになる一文 「◯◯が、◯◯から◯◯になった」
A39: 4. 使っている機能と、不満・要望
A40: 機能 | B40: 使い方（選ぶ） | D40: 使っていない理由
A41: 注文・会計・伝票
A42: セット料金・延長・指名・付け回し（夜）
A43: QR注文・厨房の画面（昼）
A44: 打刻・シフト
A45: 給料・バックの計算
A46: スタッフ・キャストのスマホ画面
A47: 顧客・ボトル・売掛・ポイント
A48: お金・日報・利益
A49: AI面接
A50: いちばん助かっている機能は？それはなぜ？
A51: 使いにくいところ・わかりにくいところは？
...

Sheet 店舗3
A1: ポスポス 導入店の聞き取りシート
A2: 黄色のセルに書き込みます。灰色のセルは自動で計算します。数字は実際に測ったものだけを書き、わからないところは空けておきます（広告に使うのは測った数字だけ）。
A4: 1. お店の情報
A5: 聞いた日
A6: お店の名前
A7: お店の種類
A8: 話を聞いた人（役職）
A9: 使い始めた日
A10: プラン
A11: 店舗数
A12: スタッフ・キャストの人数
A13: 前に使っていたレジ・管理の方法
... A23: 3. 数字で測ること
A24: 測ること | B24: 単位 | C24: 導入前 | D24: 今 | E24: 減った量 | F24: 減った割合 | G24: どうやって測ったか
A25: 閉店後の締め（売上の集計・レジ締め） | B25: 分／日 | E25: =IF(OR(C25="",D25=""),"",C25-D25) | F25: =IF(OR(C25="",D25="",N(C25)=0),"",(C25-D25)/C25)
A26: 給料の計算（バック・時給・手当を含む） | B26: 時間／月 | E26: =IF(OR(C26="",D26=""),"",C26-D26) | F26: =IF(OR(C26="",D26="",N(C26)=0),"",(C26-D26)/C26)
A27: シフトを集めて決める時間 | B27: 時間／月 | E27: =IF(OR(C27="",D27=""),"",C27-D27) | F27: =IF(OR(C27="",D27="",N(C27)=0),"",(C27-D27)/C27)
A28: 給料・バックの問い合わせ | B28: 回／月 | E28: =IF(OR(C28="",D28=""),"",C28-D28) | F28: =IF(OR(C28="",D28="",N(C28)=0),"",(C28-D28)/C28)
A29: 計算のまちがい・やり直し | B29: 回／月 | E29: =IF(OR(C29="",D29=""),"",C29-D29) | F29: =IF(OR(C29="",D29="",N(C29)=0),"",(C29-D29)/C29)
A30: 面接にかけた時間 | B30: 分／人 | E30: =IF(OR(C30="",D30=""),"",C30-D30) | F30: =IF(OR(C30="",D30="",N(C30)=0),"",(C30-D30)/C30)
A31: 面接のドタキャン・来ない | B31: 人／月 | E31: =IF(OR(C31="",D31=""),"",C31-D31) | F31: =IF(OR(C31="",D31="",N(C31)=0),"",(C31-D31)/C31)
A32: 合わなかった体入（夜のお店） | B32: 人／月 | E32: =IF(OR(C32="",D32=""),"",C32-D32) | F32: =IF(OR(C32="",D32="",N(C32)=0),"",(C32-D32)/C32)
A33: 合わなかった体入にかかった体入費（夜のお店） | B33: 円／月 | E33: =IF(OR(C33="",D33=""),"",C33-D33) | F33: =IF(OR(C33="",D33="",N(C33)=0),"",(C33-D33)/C33)
A34: AI面接を使った回数 | B34: 回／月 | C34: ―
A35: AI面接のあと会った人 | B35: 人／月 | C35: ―
A36: AI面接のあと採用した人 | B36: 人／月 | C36: ―
A37: 導入事例の見出しになる一文 「◯◯が、◯◯から◯◯になった」
A39: 4. 使っている機能と、不満・要望
A40: 機能 | B40: 使い方（選ぶ） | D40: 使っていない理由
A41: 注文・会計・伝票
A42: セット料金・延長・指名・付け回し（夜）
A43: QR注文・厨房の画面（昼）
A44: 打刻・シフト
A45: 給料・バックの計算
A46: スタッフ・キャストのスマホ画面
A47: 顧客・ボトル・売掛・ポイント
A48: お金・日報・利益
A49: AI面接
A50: いちばん助かっている機能は？それはなぜ？
A51: 使いにくいところ・わかりにくいところは？
...

Sheet 記入例
A1: ポスポス 導入店の聞き取りシート
A2: 黄色のセルに書き込みます。灰色のセルは自動で計算します。数字は実際に測ったものだけを書き、わからないところは空けておきます（広告に使うのは測った数字だけ）。
A4: 1. お店の情報
A5: 聞いた日 | C5: 46331
A6: お店の名前 | C6: （記入例）夜のお店A
A7: お店の種類 | C7: キャバクラ
A8: 話を聞いた人（役職） | C8: オーナー
A9: 使い始めた日 | C9: 46235
A10: プラン | C10: スタンダード
A11: 店舗数 | C11: 1店舗
A12: スタッフ・キャストの人数 | C12: キャスト12人・黒服3人
A13: 前に使っていたレジ・管理の方法 | C13: 紙の伝票＋Excel
A15: 2. 導入する前の困りごとと、選んだ理由（お店の人の言葉のまま）
A16: ポスポスを入れる前、いちばん面倒だった仕事は？ | C16: 閉店後、伝票を見ながらキャストごとのバックを電卓で計算するのがいちばん面倒だった
A17: それに毎日・毎月どれくらい時間がかかっていた？ | C17: 毎日の締めに40分、月末の給料計算に10時間くらい
A18: 計算ミスや、スタッフ・キャストとのもめごとはあった？
A19: 採用（面接・日程調整・体入）で困っていたことは？
A20: なぜポスポスを使ってみようと思った？ | C20: 知り合いに紹介されて、バックの計算が自動になると聞いたから
A21: ほかに比べたレジ・サービスは？選ばなかった理由は？
A23: 3. 数字で測ること
A24: 測ること | B24: 単位 | C24: 導入前 | D24: 今 | E24: 減った量 | F24: 減った割合 | G24: どうやって測ったか
A25: 閉店後の締め（売上の集計・レジ締め） | B25: 分／日 | C25: 40 | D25: 10 | E25: =IF(OR(C25="",D25=""),"",C25-D25) -> 30 | F25: =IF(OR(C25="",D25="",N(C25)=0),"",(C25-D25)/C25) -> 0.75 | G25: オーナーに直近1週間の平均を聞いた
A26: 給料の計算（バック・時給・手当を含む） | B26: 時間／月 | C26: 10 | D26: 2 | E26: =IF(OR(C26="",D26=""),"",C26-D26) -> 8 | F26: =IF(OR(C26="",D26="",N(C26)=0),"",(C26-D26)/C26) -> 0.8 | G26: 先月の給料計算にかかった時間
A27: シフトを集めて決める時間 | B27: 時間／月 | E27: =IF(OR(C27="",D27=""),"",C27-D27) | F27: =IF(OR(C27="",D27="",N(C27)=0),"",(C27-D27)/C27)
A28: 給料・バックの問い合わせ | B28: 回／月 | C28: 15 | D28: 3 | E28: =IF(OR(C28="",D28=""),"",C28-D28) -> 12 | F28: =IF(OR(C28="",D28="",N(C28)=0),"",(C28-D28)/C28) -> 0.8
A29: 計算のまちがい・やり直し | B29: 回／月 | E29: =IF(OR(C29="",D29=""),"",C29-D29) | F29: =IF(OR(C29="",D29="",N(C29)=0),"",(C29-D29)/C29)
A30: 面接にかけた時間 | B30: 分／人 | E30: =IF(OR(C30="",D30=""),"",C30-D30) | F30: =IF(OR(C30="",D30="",N(C30)=0),"",(C30-D30)/C30)
A31: 面接のドタキャン・来ない | B31: 人／月 | E31: =IF(OR(C31="",D31=""),"",C31-D31) | F31: =IF(OR(C31="",D31="",N(C31)=0),"",(C31-D31)/C31)
A32: 合わなかった体入（夜のお店） | B32: 人／月 | E32: =IF(OR(C32="",D32=""),"",C32-D32) | F32: =IF(OR(C32="",D32="",N(C32)=0),"",(C32-D32)/C32)
A33: 合わなかった体入にかかった体入費（夜のお店） | B33: 円／月 | E33: =IF(OR(C33="",D33=""),"",C33-D33) | F33: =IF(OR(C33="",D33="",N(C33)=0),"",(C33-D33)/C33)
A34: AI面接を使った回数 | B34: 回／月 | C34: ― | D34: 6 | G34: 管理画面のAI面接の一覧で数えた
A35: AI面接のあと会った人 | B35: 人／月 | C35: ― | D35: 3
A36: AI面接のあと採用した人 | B36: 人／月 | C36: ― | D36: 1
A37: 導入事例の見出しになる一文 「◯◯が、◯◯から◯◯になった」 | C37: キャストの給料計算が、月10時間から2時間になった（記入例）
A39: 4. 使っている機能と、不満・要望
A40: 機能 | B40: 使い方（選ぶ） | D40: 使っていない理由
A41: 注文・会計・伝票 | B41: 毎日使う
A42: セット料金・延長・指名・付け回し（夜）
A43: QR注文・厨房の画面（昼）
A44: 打刻・シフト
...
